<?xml version="1.0"?>
<robot xmlns:xacro="http://www.ros.org/wiki/xacro" name="pendulum_gripper">
  <xacro:macro name="pendulum_gripper" params="side">
    <!-- Base of end effector -->
    <link name="${side}_gripper_base">
      <visual>
        <origin rpy="${-pi/2} ${pi} 0" xyz="0 0 0"/>
        <geometry>
          <mesh filename="package://rethink_ee_description/meshes/electric_gripper/electric_gripper_base.DAE"/>
        </geometry>
      </visual>
      <collision>
        <origin rpy="${-pi/2} ${pi} 0" xyz="0.0 0.0 0"/>
        <geometry>
          <cylinder length="0.1" radius="0.029"/>
        </geometry>
        <material name="darkred">
          <color rgba=".5 .1 .1 1"/>
        </material>
      </collision>
      <inertial>
        <origin rpy="${-pi/2} ${pi} 0" xyz="0.0 0.0 0.0"/>
        <mass value="0.3"/>
        <inertia ixx="2e-08" ixy="0" ixz="0" iyy="3e-08" iyz="0" izz="2e-08"/>
      </inertial>
    </link>


    <!-- Pendulum Base Joint -->
    <joint name="${side}_gripper_base_joint" type="fixed">
      <origin rpy="0.0 0.0 0.0" xyz="0 0 0.025"/>
      <parent link="${side}_hand"/>
      <child link="${side}_gripper_base"/>
    </joint>

    <link name="${side}_gripper">
      <inertial>
        <origin rpy="0 0 0" xyz="0 0 0"/>
        <mass value="0.0001"/>
        <inertia ixx="0" ixy="0" ixz="0" iyy="0" iyz="0" izz="0.0"/>
      </inertial>
    </link>

    <joint name="${side}_endpoint" type="fixed">
      <origin rpy="0 0 0" xyz="0 0 0"/>
      <parent link="${side}_gripper_base"/>
      <child link="${side}_gripper"/>
    </joint>


    <!-- Pendulum Phi joint -->
    <link name="${side}_pendulum_phi">
      <inertial>
        <origin rpy="0 0 0" xyz="0 0 0"/>
        <mass value="0.0001"/>
        <inertia ixx="0" ixy="0" ixz="0" iyy="0" iyz="0" izz="0.0"/>
      </inertial>
    </link>

    <joint name="${side}_pendulum_phi_joint" type="revolute">
      <origin rpy="0.0 0.0 0.0" xyz="0.0 0.0 0.0"/>
      <axis xyz="0 0 1"/>
      <limit effort="0.0" velocity="10.0" lower="${-pi/2}" upper ="${pi/2}"/>
      <parent link="${side}_gripper"/>
      <child link="${side}_pendulum_phi"/>
    </joint>

    <!-- Pendulum Theta joint -->
    <link name="${side}_pendulum_theta">
      <inertial>
        <origin rpy="0 0 0" xyz="0 0 0"/>
        <mass value="0.0001"/>
        <inertia ixx="0" ixy="0" ixz="0" iyy="0" iyz="0" izz="0.0"/>
      </inertial>
    </link>

    <joint name="${side}_pendulum_theta_joint" type="revolute">
      <origin rpy="0.0 0.0 0.0" xyz="0.0 0.0 0.0"/>
      <axis xyz="0 1 0" />
      <limit effort="0.0" velocity="10.0" lower="${-pi/2}" upper ="${pi/2}"/>
      <parent link="${side}_pendulum_phi"/>
      <child link="${side}_pendulum_theta"/>
    </joint>

    <!-- Actual Pendulum -->
    <link name="${side}_pendulum">
      <inertial>
        <origin rpy="0.0 ${pi/2} 0.0" xyz="-0.807 0.0 0.0"/>
        <mass value="0.326"/>
        <!--<mass value="0.00001"/>-->
        <inertia ixx="0.5966" ixy="0.0" ixz="0.0" iyy="0.5966" iyz="0.0" izz="0.5966"/>
      </inertial>
      <visual>
        <origin rpy="0.0 ${pi/2} 0.0" xyz="-0.807 0.0 0.0"/>
        <geometry>
          <cylinder length="1.614" radius="0.01"/>
        </geometry>
      </visual>
      <!--<collision>-->
        <!--<origin rpy="0.0 ${pi/2} 0" xyz="-0.807 0.0 0.0"/>-->
        <!--<geometry>-->
          <!--<cylinder length="1.614" radius="0.01"/>-->
        <!--</geometry>-->
      <!--</collision>-->
    </link>

    <joint name="${side}_pendulum_joint" type="fixed">
      <origin rpy="0.0 0.0 0.0" xyz="0.0 0.0 0.0"/>
      <parent link="${side}_pendulum_theta"/>
      <child link="${side}_pendulum"/>
    </joint>

    <gazebo reference="${side}_gripper_base_joint">
        <implicitSpringDamper>1</implicitSpringDamper>
    </gazebo>
    <gazebo reference="${side}_gripper_joint">
      <implicitSpringDamper>1</implicitSpringDamper>
    </gazebo>
    <gazebo reference="${side}_endpoint_joint">
      <implicitSpringDamper>1</implicitSpringDamper>
    </gazebo>
    <gazebo reference="${side}_pendulum_phi_joint">
      <implicitSpringDamper>1</implicitSpringDamper>
    </gazebo>
    <gazebo reference="${side}_pendulum_theta_joint">
      <implicitSpringDamper>1</implicitSpringDamper>
    </gazebo>
    <gazebo reference="${side}_pendulum_joint">
      <implicitSpringDamper>1</implicitSpringDamper>
    </gazebo>
    <gazebo reference="${side}_pendulum">
      <material>Gazebo/Orange</material>
    </gazebo>

    <!--gazebo plugin for pendulum pose-->
    <gazebo>
      <plugin filename="libpose_plugin.so" name="pendulum_pose_sensor">
        <linkName>${side}_pendulum_theta</linkName>
        <namespace>/robot/pendulum</namespace>
      </plugin>
    </gazebo>

  </xacro:macro>
</robot>
